Workbook

Sheet SKU'S
A1: BRSTW-60-FD | C1: Last update: 5/28/2026
A2: BRSTW-60-CS-LY
A3: BRSTW-60-CS-EG
A4: FERTMX-30-CS-VT
A5: FERTMX-40-FD
A6: FERTMX-90-FD
A7: FERTMX-90-RE
A8: FERTMX-90-CS-BN
A9: FERTMX-90-CS-AN
A10: FERTMX-90-CS-VT
A11: FERTMX-90-CS-TA
A12: FERTMX-90-CS-NI
A13: FERTMX-60-RE
... A56: MFSPLS-120-CS-CN
A57: 604776737582
A58: MFSPLS-120-CS-NI
A59: MFSPLS-120-CS-UG
A60: MFSPLS-120-CS-KW
A61: MFS-120-CS-RW
A62: MFSPLS-120-FD
A63: MFSPLS-120-CS-TA
A64: MFSPLS-120-CS-EG
A65: MFSPLS-120-CS-LY
A66: MFSPLS-60-RE
A67: MFSPLS-60-FD
A68: MFSPLS-60-CS-BN
A69: MFSPLS-60-CS-AN
... A369: ZINC50-30-CS-IQ

Sheet Allocation Dashboard (Take)
B1: Taking Opportunities | AG1: Product Needed | AK1: {=_xlfn.TEXTJOIN("-",,INDEX(_xlfn.TEXTSPLIT(AH2,"-"),{1,2}))} -> #VALUE!
A2: Date of Order | B2: Customer | C2: Order # | D2: Sales Personal Notes | E2: Order Details | F2: Notes: Include all notes week by week | G2: SKU | H2: Product | I2: Label | J2: QTY on Order | K2: Labels/IFC- Version/batch | L2: QTY Commited | M2: Column4 | N2: Status | O2: Notes | P2: IFC | Q2: UPC Code | R2: QTY on Order2 | S2: Item PO | T2: EST Manufacture Completion | U2: Notes: | V2: Lot Number | W2: Notes: Include all notes week by week3 | X2: Order ETA ** only for products in rework** | Y2: Date Completed D/W Sent | Z2: Status4 | AA2: Column2 | AB2: Column1 | AC2: QTY Fuffilled? | AD2: Peeling? | AE2: Column3 | AG2: SKU: | AI2: QTY: | AK2: =_xlfn.TEXTAFTER(AH2,"-", -1) -> #VALUE!
A3: ='[1]2026 Orders'!A4 -> 45726 | B3: ='[1]2026 Orders'!B4 -> China | C3: ='[1]2026 Orders'!C4 -> A4458 | D3: ='[1]2026 Orders'!D4 -> 0 | E3: {=IF(C3=0,"", HYPERLINK( "#'2026 Orders'!C"& MATCH(1, ('2026 Orders'!C:C=C3)* ('2026 Orders'!G:G=G3)* ('2026 Orders'!N:N=N3), 0), "Open "&C3 ))} -> Open A4458 | F3: ='[1]2026 Orders'!F4 -> 0 | G3: ='[1]2026 Orders'!G4 -> SELENIU-60-FD | H3: {=IFERROR(_xlfn.TEXTJOIN("-",,INDEX(_xlfn.TEXTSPLIT(TableTake[[#This Row],[SKU]],"-"),{1,2})),"")} -> SELENIU-60 | I3: =IFERROR(_xlfn.TEXTAFTER(TableTake[[#This Row],[SKU]],"-",-1),"") -> FD | J3: ='[1]2026 Orders'!H4 -> 200 | K3: ='[1]2026 Orders'!I4 -> F63-25.1 | L3: MFSPLS-120-FD | N3: ='[1]2026 Orders'!L4 -> D/W Sent | O3: ='[1]2026 Orders'!M4 -> 12/15 D/W Sent | P3: ='[1]2026 Orders'!N4 -> NA | Q3: ='[1]2026 Orders'!O4 -> 604776735762 | R3: ='[1]2026 Orders'!P4 -> 3000 | S3: ='[1]2026 Orders'!Q4 -> 4833 | T3: ='[1]2026 Orders'!R4 -> complete | U3: ='[1]2026 Orders'!S4 -> 0 | ... Z3: ='[1]2026 Orders'!X4 -> Approved 01/16/26 | AC3: =IF(OR(B3="",B3=0),"",J3&"/"&$AJ$2) -> 200/ | AD3: =IF(OR(J3="",J3=0),"",I3&" -> "&$AK$2) -> #VALUE!
A4: ='[1]2026 Orders'!A5 -> 0 | B4: ='[1]2026 Orders'!B5 -> 0 | C4: ='[1]2026 Orders'!C5 -> 0 | D4: ='[1]2026 Orders'!D5 -> 0 | E4: {=IF(C4=0,"", HYPERLINK( "#'2026 Orders'!C"& MATCH(1, ('2026 Orders'!C:C=C4)* ('2026 Orders'!G:G=G4)* ('2026 Orders'!N:N=N4), 0), "Open "&C4 ))} | F4: ='[1]2026 Orders'!F5 -> 0 | G4: ='[1]2026 Orders'!G5 -> 0 | H4: {=IFERROR(_xlfn.TEXTJOIN("-",,INDEX(_xlfn.TEXTSPLIT(TableTake[[#This Row],[SKU]],"-"),{1,2})),"")} | I4: =IFERROR(_xlfn.TEXTAFTER(TableTake[[#This Row],[SKU]],"-",-1),"") | J4: ='[1]2026 Orders'!H5 -> 0 | K4: ='[1]2026 Orders'!I5 -> 0 | L4: 817 | N4: ='[1]2026 Orders'!L5 -> 0 | O4: ='[1]2026 Orders'!M5 -> 0 | P4: ='[1]2026 Orders'!N5 -> 0 | Q4: ='[1]2026 Orders'!O5 -> 0 | R4: ='[1]2026 Orders'!P5 -> 0 | S4: ='[1]2026 Orders'!Q5 -> 0 | T4: ='[1]2026 Orders'!R5 -> 0 | U4: ='[1]2026 Orders'!S5 -> 0 | ... Z4: ='[1]2026 Orders'!X5 -> 0 | AC4: =IF(OR(B4="",B4=0),"",J4&"/"&$AJ$2) | AD4: =IF(OR(J4="",J4=0),"",I4&" -> "&$AK$2)
A5: ='[1]2026 Orders'!A6 -> 45443 | B5: ='[1]2026 Orders'!B6 -> China | C5: ='[1]2026 Orders'!C6 -> A4425 | D5: ='[1]2026 Orders'!D6 -> 0 | E5: {=IF(C5=0,"", HYPERLINK( "#'2026 Orders'!C"& MATCH(1, ('2026 Orders'!C:C=C5)* ('2026 Orders'!G:G=G5)* ('2026 Orders'!N:N=N5), 0), "Open "&C5 ))} -> Open A4425 | F5: ='[1]2026 Orders'!F6 -> 0 | G5: ='[1]2026 Orders'!G6 -> VIACAL-60-FD | H5: {=IFERROR(_xlfn.TEXTJOIN("-",,INDEX(_xlfn.TEXTSPLIT(TableTake[[#This Row],[SKU]],"-"),{1,2})),"")} -> VIACAL-60 | I5: =IFERROR(_xlfn.TEXTAFTER(TableTake[[#This Row],[SKU]],"-",-1),"") -> FD | J5: ='[1]2026 Orders'!H6 -> 200 | K5: ='[1]2026 Orders'!I6 -> F66-22.1 | L5: ='[1]2026 Orders'!J6 -> 200 | N5: ='[1]2026 Orders'!L6 -> D/W Sent | O5: ='[1]2026 Orders'!M6 -> 01/13 D/W Sent | P5: ='[1]2026 Orders'!N6 -> NA | Q5: ='[1]2026 Orders'!O6 -> 609788968160 | R5: ='[1]2026 Orders'!P6 -> 2000 | S5: ='[1]2026 Orders'!Q6 -> 4661 | T5: ='[1]2026 Orders'!R6 -> complete | U5: ='[1]2026 Orders'!S6 -> 0 | ... Z5: ='[1]2026 Orders'!X6 -> Approved | AC5: =IF(OR(B5="",B5=0),"",J5&"/"&$AJ$2) -> 200/ | AD5: =IF(OR(J5="",J5=0),"",I5&" -> "&$AK$2) -> #VALUE!
A6: ='[1]2026 Orders'!A7 -> 0 | B6: ='[1]2026 Orders'!B7 -> 0 | C6: ='[1]2026 Orders'!C7 -> 0 | D6: ='[1]2026 Orders'!D7 -> 0 | E6: {=IF(C6=0,"", HYPERLINK( "#'2026 Orders'!C"& MATCH(1, ('2026 Orders'!C:C=C6)* ('2026 Orders'!G:G=G6)* ('2026 Orders'!N:N=N6), 0), "Open "&C6 ))} | F6: ='[1]2026 Orders'!F7 -> 0 | G6: ='[1]2026 Orders'!G7 -> 0 | H6: {=IFERROR(_xlfn.TEXTJOIN("-",,INDEX(_xlfn.TEXTSPLIT(TableTake[[#This Row],[SKU]],"-"),{1,2})),"")} | I6: =IFERROR(_xlfn.TEXTAFTER(TableTake[[#This Row],[SKU]],"-",-1),"") | J6: ='[1]2026 Orders'!H7 -> 0 | K6: ='[1]2026 Orders'!I7 -> 0 | L6: ='[1]2026 Orders'!J7 -> 0 | N6: ='[1]2026 Orders'!L7 -> 0 | O6: ='[1]2026 Orders'!M7 -> 0 | P6: ='[1]2026 Orders'!N7 -> 0 | Q6: ='[1]2026 Orders'!O7 -> 0 | R6: ='[1]2026 Orders'!P7 -> 0 | S6: ='[1]2026 Orders'!Q7 -> 0 | T6: ='[1]2026 Orders'!R7 -> 0 | U6: ='[1]2026 Orders'!S7 -> 0 | ... Z6: ='[1]2026 Orders'!X7 -> 0 | AC6: =IF(OR(B6="",B6=0),"",J6&"/"&$AJ$2) | AD6: =IF(OR(J6="",J6=0),"",I6&" -> "&$AK$2)
A7: ='[1]2026 Orders'!A8 -> 45589 | B7: ='[1]2026 Orders'!B8 -> UAE | C7: ='[1]2026 Orders'!C8 -> A4624 | D7: ='[1]2026 Orders'!D8 -> Under going registration in UAE 5/13/2026: UAE unable to take, exploring if other clients can take product. | E7: {=IF(C7=0,"", HYPERLINK( "#'2026 Orders'!C"& MATCH(1, ('2026 Orders'!C:C=C7)* ('2026 Orders'!G:G=G7)* ('2026 Orders'!N:N=N7), 0), "Open "&C7 ))} -> #N/A | F7: ='[1]2026 Orders'!F8 -> 6/13/2025: products added from UAE A4393 9/5/2025: 96 packs allocated to Amazon 9/18/2025: Moved from A4445 | G7: ='[1]2026 Orders'!G8 -> NERUFLX-60-FD | H7: {=IFERROR(_xlfn.TEXTJOIN("-",,INDEX(_xlfn.TEXTSPLIT(TableTake[[#This Row],[SKU]],"-"),{1,2})),"")} -> NERUFLX-60 | I7: =IFERROR(_xlfn.TEXTAFTER(TableTake[[#This Row],[SKU]],"-",-1),"") -> FD | J7: ='[1]2026 Orders'!H8 -> 1054 | K7: ='[1]2026 Orders'!I8 -> F115-25.0 | L7: ='[1]2026 Orders'!J8 -> 1054 | N7: ='[1]2026 Orders'!L8 -> Sales Action Needed | O7: ='[1]2026 Orders'!M8 -> 01/20 D/W Sent | P7: ='[1]2026 Orders'!N8 -> Y | Q7: ='[1]2026 Orders'!O8 -> 810131193164 | R7: ='[1]2026 Orders'!P8 -> 2500 | S7: ='[1]2026 Orders'!Q8 -> 4524 | T7: ='[1]2026 Orders'!R8 -> complete | U7: ='[1]2026 Orders'!S8 -> 0 | ... Z7: ='[1]2026 Orders'!X8 -> HOLD | AC7: =IF(OR(B7="",B7=0),"",J7&"/"&$AJ$2) -> 1054/ | AD7: =IF(OR(J7="",J7=0),"",I7&" -> "&$AK$2) -> #VALUE!
A8: ='[1]2026 Orders'!A9 -> 46058 | B8: ='[1]2026 Orders'!B9 -> 0 | C8: ='[1]2026 Orders'!C9 -> A4553 | D8: ='[1]2026 Orders'!D9 -> 5/13/2026: *DO NOT PREPARE ORDER FOR SHIPMENT YET: ADDITIONAL PRODUCTS TO BE ADDED* | E8: {=IF(C8=0,"", HYPERLINK( "#'2026 Orders'!C"& MATCH(1, ('2026 Orders'!C:C=C8)* ('2026 Orders'!G:G=G8)* ('2026 Orders'!N:N=N8), 0), "Open "&C8 ))} -> #N/A | F8: ='[1]2026 Orders'!F9 -> 3/30/2026: Moved from UAE A4644 | G8: ='[1]2026 Orders'!G9 -> MFSPLS-120-RE | H8: {=IFERROR(_xlfn.TEXTJOIN("-",,INDEX(_xlfn.TEXTSPLIT(TableTake[[#This Row],[SKU]],"-"),{1,2})),"")} -> MFSPLS-120 | I8: =IFERROR(_xlfn.TEXTAFTER(TableTake[[#This Row],[SKU]],"-",-1),"") -> RE | J8: ='[1]2026 Orders'!H9 -> 1050 | K8: ='[1]2026 Orders'!I9 -> 0 | L8: ='[1]2026 Orders'!J9 -> 1050 | N8: ='[1]2026 Orders'!L9 -> Picked | O8: ='[1]2026 Orders'!M9 -> 0 | P8: ='[1]2026 Orders'!N9 -> NA | Q8: ='[1]2026 Orders'!O9 -> 609788968344 | R8: ='[1]2026 Orders'!P9 -> 7000 | S8: ='[1]2026 Orders'!Q9 -> 4935 | T8: ='[1]2026 Orders'!R9 -> complete | U8: ='[1]2026 Orders'!S9 -> 0 | ... Z8: ='[1]2026 Orders'!X9 -> 0 | AC8: =IF(OR(B8="",B8=0),"",J8&"/"&$AJ$2) | AD8: =IF(OR(J8="",J8=0),"",I8&" -> "&$AK$2) -> #VALUE!
A9: ='[1]2026 Orders'!A10 -> 45880 | B9: ='[1]2026 Orders'!B10 -> Kuwait | C9: ='[1]2026 Orders'!C10 -> A4562 | D9: ='[1]2026 Orders'!D10 -> 5/11/2026: Order on hold | E9: {=IF(C9=0,"", HYPERLINK( "#'2026 Orders'!C"& MATCH(1, ('2026 Orders'!C:C=C9)* ('2026 Orders'!G:G=G9)* ('2026 Orders'!N:N=N9), 0), "Open "&C9 ))} -> Open A4562 | F9: ='[1]2026 Orders'!F10 -> 11/3/2025: Waiting for registration 11/5/2025: Allocated 500 packs to UAE A4521 | G9: ='[1]2026 Orders'!G10 -> EYECAP-30-FD | H9: {=IFERROR(_xlfn.TEXTJOIN("-",,INDEX(_xlfn.TEXTSPLIT(TableTake[[#This Row],[SKU]],"-"),{1,2})),"")} -> EYECAP-30 | I9: =IFERROR(_xlfn.TEXTAFTER(TableTake[[#This Row],[SKU]],"-",-1),"") -> FD | J9: ='[1]2026 Orders'!H10 -> 500 | K9: ='[1]2026 Orders'!I10 -> F15-26.0 | L9: ='[1]2026 Orders'!J10 -> 0 | N9: ='[1]2026 Orders'!L10 -> ON HOLD | O9: ='[1]2026 Orders'!M10 -> 0 | P9: ='[1]2026 Orders'!N10 -> Y | Q9: ='[1]2026 Orders'!O10 -> 609788968443 | R9: ='[1]2026 Orders'!P10 -> 0 | S9: ='[1]2026 Orders'!Q10 -> 0 | T9: ='[1]2026 Orders'!R10 -> 0 | U9: ='[1]2026 Orders'!S10 -> MOQ 5000 | ... Z9: ='[1]2026 Orders'!X10 -> HOLD | AC9: =IF(OR(B9="",B9=0),"",J9&"/"&$AJ$2) -> 500/ | AD9: =IF(OR(J9="",J9=0),"",I9&" -> "&$AK$2) -> #VALUE!
A10: ='[1]2026 Orders'!A11 -> 46141 | B10: ='[1]2026 Orders'!B11 -> UAE | C10: ='[1]2026 Orders'!C11 -> A4553 | D10: ='[1]2026 Orders'!D11 -> 0 | E10: {=IF(C10=0,"", HYPERLINK( "#'2026 Orders'!C"& MATCH(1, ('2026 Orders'!C:C=C10)* ('2026 Orders'!G:G=G10)* ('2026 Orders'!N:N=N10), 0), "Open "&C10 ))} -> #N/A | F10: ='[1]2026 Orders'!F11 -> 4/29/2026: Product added 5/4/2026: Qty changed 183 -> 182 | G10: ='[1]2026 Orders'!G11 -> POLYSIT-90-RE | H10: {=IFERROR(_xlfn.TEXTJOIN("-",,INDEX(_xlfn.TEXTSPLIT(TableTake[[#This Row],[SKU]],"-"),{1,2})),"")} -> POLYSIT-90 | I10: =IFERROR(_xlfn.TEXTAFTER(TableTake[[#This Row],[SKU]],"-",-1),"") -> RE | J10: ='[1]2026 Orders'!H11 -> 182 | K10: ='[1]2026 Orders'!I11 -> 0 | L10: ='[1]2026 Orders'!J11 -> 182 | N10: ='[1]2026 Orders'!L11 -> 0 | O10: ='[1]2026 Orders'!M11 -> 182 available Lot: 49311125 | P10: ='[1]2026 Orders'!N11 -> Y | Q10: ='[1]2026 Orders'!O11 -> 609788969006 | R10: ='[1]2026 Orders'!P11 -> 0 | S10: ='[1]2026 Orders'!Q11 -> 0 | T10: ='[1]2026 Orders'!R11 -> 0 | U10: ='[1]2026 Orders'!S11 -> 0 | ... Z10: ='[1]2026 Orders'!X11 -> 0 | AC10: =IF(OR(B10="",B10=0),"",J10&"/"&$AJ$2) -> 182/ | AD10: =IF(OR(J10="",J10=0),"",I10&" -> "&$AK$2) -> #VALUE!
A11: ='[1]2026 Orders'!A12 -> 45890 | B11: ='[1]2026 Orders'!B12 -> Uganda | C11: ='[1]2026 Orders'!C12 -> A4522 | D11: ='[1]2026 Orders'!D12 -> 0 | E11: {=IF(C11=0,"", HYPERLINK( "#'2026 Orders'!C"& MATCH(1, ('2026 Orders'!C:C=C11)* ('2026 Orders'!G:G=G11)* ('2026 Orders'!N:N=N11), 0), "Open "&C11 ))} -> Open A4522 | F11: ='[1]2026 Orders'!F12 -> 0 | G11: ='[1]2026 Orders'!G12 -> SPERMCT-60-FD | H11: {=IFERROR(_xlfn.TEXTJOIN("-",,INDEX(_xlfn.TEXTSPLIT(TableTake[[#This Row],[SKU]],"-"),{1,2})),"")} -> SPERMCT-60 | I11: =IFERROR(_xlfn.TEXTAFTER(TableTake[[#This Row],[SKU]],"-",-1),"") -> FD | J11: ='[1]2026 Orders'!H12 -> 96 | K11: ='[1]2026 Orders'!I12 -> F64-25.0 | L11: ='[1]2026 Orders'!J12 -> 96 | N11: ='[1]2026 Orders'!L12 -> Picked | O11: ='[1]2026 Orders'!M12 -> 0 | P11: ='[1]2026 Orders'!N12 -> NA | Q11: ='[1]2026 Orders'!O12 -> 609788968405 | R11: ='[1]2026 Orders'!P12 -> 5500 | S11: ='[1]2026 Orders'!Q12 -> 4850 | T11: ='[1]2026 Orders'!R12 -> complete | U11: ='[1]2026 Orders'!S12 -> 0 | ... Z11: ='[1]2026 Orders'!X12 -> HOLD | AC11: =IF(OR(B11="",B11=0),"",J11&"/"&$AJ$2) -> 96/ | AD11: =IF(OR(J11="",J11=0),"",I11&" -> "&$AK$2) -> #VALUE!
A12: ='[1]2026 Orders'!A13 -> 45890 | B12: ='[1]2026 Orders'!B13 -> Uganda | C12: ='[1]2026 Orders'!C13 -> A4522 | D12: ='[1]2026 Orders'!D13 -> 0 | E12: {=IF(C12=0,"", HYPERLINK( "#'2026 Orders'!C"& MATCH(1, ('2026 Orders'!C:C=C12)* ('2026 Orders'!G:G=G12)* ('2026 Orders'!N:N=N12), 0), "Open "&C12 ))} -> Open A4522 | F12: ='[1]2026 Orders'!F13 -> 5/12/2026: Allocating to Lebanon A4690. | G12: ='[1]2026 Orders'!G13 -> WFSPLS-180-FD | H12: {=IFERROR(_xlfn.TEXTJOIN("-",,INDEX(_xlfn.TEXTSPLIT(TableTake[[#This Row],[SKU]],"-"),{1,2})),"")} -> WFSPLS-180 | I12: =IFERROR(_xlfn.TEXTAFTER(TableTake[[#This Row],[SKU]],"-",-1),"") -> FD | J12: ='[1]2026 Orders'!H13 -> 120 | K12: ='[1]2026 Orders'!I13 -> F73-23.0 | L12: ='[1]2026 Orders'!J13 -> 120 | N12: ='[1]2026 Orders'!L13 -> PO Drafted | O12: ='[1]2026 Orders'!M13 -> 46012 | P12: ='[1]2026 Orders'!N13 -> NA | Q12: ='[1]2026 Orders'!O13 -> 609788968351 | R12: ='[1]2026 Orders'!P13 -> 5000 | S12: ='[1]2026 Orders'!Q13 -> 5043 | T12: ='[1]2026 Orders'!R13 -> TBD | U12: ='[1]2026 Orders'!S13 -> Pending approval to send to vendor | ... Z12: ='[1]2026 Orders'!X13 -> 0 | AC12: =IF(OR(B12="",B12=0),"",J12&"/"&$AJ$2) -> 120/ | AD12: =IF(OR(J12="",J12=0),"",I12&" -> "&$AK$2) -> #VALUE!
A13: ='[1]2026 Orders'!A14 -> 45890 | B13: ='[1]2026 Orders'!B14 -> Uganda | C13: ='[1]2026 Orders'!C14 -> A4522 | D13: ='[1]2026 Orders'!D14 -> 0 | E13: {=IF(C13=0,"", HYPERLINK( "#'2026 Orders'!C"& MATCH(1, ('2026 Orders'!C:C=C13)* ('2026 Orders'!G:G=G13)* ('2026 Orders'!N:N=N13), 0), "Open "&C13 ))} -> Open A4522 | F13: ='[1]2026 Orders'!F14 -> 9/11/2025: product changed to RE 5/14/2026: Allocate to Cyprus A4675. | G13: ='[1]2026 Orders'!G14 -> FERTMX-90-RE | H13: {=IFERROR(_xlfn.TEXTJOIN("-",,INDEX(_xlfn.TEXTSPLIT(TableTake[[#This Row],[SKU]],"-"),{1,2})),"")} -> FERTMX-90 | I13: =IFERROR(_xlfn.TEXTAFTER(TableTake[[#This Row],[SKU]],"-",-1),"") -> RE | J13: ='[1]2026 Orders'!H14 -> 288 | K13: ='[1]2026 Orders'!I14 -> R16-22.0 | L13: ='[1]2026 Orders'!J14 -> 0 | N13: ='[1]2026 Orders'!L14 -> PO submitted | O13: ='[1]2026 Orders'!M14 -> 0 | P13: ='[1]2026 Orders'!N14 -> Y | Q13: ='[1]2026 Orders'!O14 -> 609788968726 | R13: ='[1]2026 Orders'!P14 -> 5000 | S13: ='[1]2026 Orders'!Q14 -> 5041 | T13: ='[1]2026 Orders'!R14 -> TBD | U13: ='[1]2026 Orders'!S14 -> Waiting for vendor confirmation. | ... Z13: ='[1]2026 Orders'!X14 -> 0 | AC13: =IF(OR(B13="",B13=0),"",J13&"/"&$AJ$2) -> 288/ | AD13: =IF(OR(J13="",J13=0),"",I13&" -> "&$AK$2) -> #VALUE!
A14: ='[1]2026 Orders'!A15 -> 45890 | B14: ='[1]2026 Orders'!B15 -> Uganda | C14: ='[1]2026 Orders'!C15 -> A4522 | D14: ='[1]2026 Orders'!D15 -> 0 | E14: {=IF(C14=0,"", HYPERLINK( "#'2026 Orders'!C"& MATCH(1, ('2026 Orders'!C:C=C14)* ('2026 Orders'!G:G=G14)* ('2026 Orders'!N:N=N14), 0), "Open "&C14 ))} -> Open A4522 | F14: ='[1]2026 Orders'!F15 -> 0 | G14: ='[1]2026 Orders'!G15 -> PRECON-90-FD | H14: {=IFERROR(_xlfn.TEXTJOIN("-",,INDEX(_xlfn.TEXTSPLIT(TableTake[[#This Row],[SKU]],"-"),{1,2})),"")} -> PRECON-90 | I14: =IFERROR(_xlfn.TEXTAFTER(TableTake[[#This Row],[SKU]],"-",-1),"") -> FD | J14: ='[1]2026 Orders'!H15 -> 120 | K14: ='[1]2026 Orders'!I15 -> F54-23.0 | L14: ='[1]2026 Orders'!J15 -> 120 | N14: ='[1]2026 Orders'!L15 -> Picked | O14: ='[1]2026 Orders'!M15 -> 0 | P14: ='[1]2026 Orders'!N15 -> NA | Q14: ='[1]2026 Orders'!O15 -> 609788968368 | R14: ='[1]2026 Orders'!P15 -> 7500 | S14: ='[1]2026 Orders'!Q15 -> 4714 | T14: ='[1]2026 Orders'!R15 -> complete | U14: ='[1]2026 Orders'!S15 -> 0 | ... Z14: ='[1]2026 Orders'!X15 -> 0 | AC14: =IF(OR(B14="",B14=0),"",J14&"/"&$AJ$2) -> 120/ | AD14: =IF(OR(J14="",J14=0),"",I14&" -> "&$AK$2) -> #VALUE!
A15: ='[1]2026 Orders'!A16 -> 45890 | B15: ='[1]2026 Orders'!B16 -> Uganda | C15: ='[1]2026 Orders'!C16 -> A4522 | D15: ='[1]2026 Orders'!D16 -> 0 | E15: {=IF(C15=0,"", HYPERLINK( "#'2026 Orders'!C"& MATCH(1, ('2026 Orders'!C:C=C15)* ('2026 Orders'!G:G=G15)* ('2026 Orders'!N:N=N15), 0), "Open "&C15 ))} -> Open A4522 | F15: ='[1]2026 Orders'!F16 -> 0 | G15: ='[1]2026 Orders'!G16 -> QWELL4-30-SG-FD | H15: {=IFERROR(_xlfn.TEXTJOIN("-",,INDEX(_xlfn.TEXTSPLIT(TableTake[[#This Row],[SKU]],"-"),{1,2})),"")} -> QWELL4-30 | I15: =IFERROR(_xlfn.TEXTAFTER(TableTake[[#This Row],[SKU]],"-",-1),"") -> FD | J15: ='[1]2026 Orders'!H16 -> 96 | K15: ='[1]2026 Orders'!I16 -> F58-25.3 | L15: ='[1]2026 Orders'!J16 -> 96 | N15: ='[1]2026 Orders'!L16 -> Picked | O15: ='[1]2026 Orders'!M16 -> 0 | P15: ='[1]2026 Orders'!N16 -> NA | Q15: ='[1]2026 Orders'!O16 -> 609788968214 | R15: ='[1]2026 Orders'!P16 -> 17633 | S15: ='[1]2026 Orders'!Q16 -> 4858 | T15: ='[1]2026 Orders'!R16 -> complete | U15: ='[1]2026 Orders'!S16 -> 0 | ... Z15: ='[1]2026 Orders'!X16 -> 0 | AC15: =IF(OR(B15="",B15=0),"",J15&"/"&$AJ$2) -> 96/ | AD15: =IF(OR(J15="",J15=0),"",I15&" -> "&$AK$2) -> #VALUE!
A16: ='[1]2026 Orders'!A17 -> 45890 | B16: ='[1]2026 Orders'!B17 -> Uganda | C16: ='[1]2026 Orders'!C17 -> A4522 | D16: ='[1]2026 Orders'!D17 -> 0 | E16: {=IF(C16=0,"", HYPERLINK( "#'2026 Orders'!C"& MATCH(1, ('2026 Orders'!C:C=C16)* ('2026 Orders'!G:G=G16)* ('2026 Orders'!N:N=N16), 0), "Open "&C16 ))} -> Open A4522 | F16: ='[1]2026 Orders'!F17 -> 0 | G16: ='[1]2026 Orders'!G17 -> PROSTA-90-FD | H16: {=IFERROR(_xlfn.TEXTJOIN("-",,INDEX(_xlfn.TEXTSPLIT(TableTake[[#This Row],[SKU]],"-"),{1,2})),"")} -> PROSTA-90 | I16: =IFERROR(_xlfn.TEXTAFTER(TableTake[[#This Row],[SKU]],"-",-1),"") -> FD | J16: ='[1]2026 Orders'!H17 -> 24 | K16: ='[1]2026 Orders'!I17 -> F56-23.0 | L16: ='[1]2026 Orders'!J17 -> 24 | N16: ='[1]2026 Orders'!L17 -> Picked | O16: ='[1]2026 Orders'!M17 -> 0 | P16: ='[1]2026 Orders'!N17 -> NA | Q16: ='[1]2026 Orders'!O17 -> 609788968504 | R16: ='[1]2026 Orders'!P17 -> 4000 | S16: ='[1]2026 Orders'!Q17 -> 4802 | T16: ='[1]2026 Orders'!R17 -> complete | U16: ='[1]2026 Orders'!S17 -> 0 | ... Z16: ='[1]2026 Orders'!X17 -> 0 | AC16: =IF(OR(B16="",B16=0),"",J16&"/"&$AJ$2) -> 24/ | AD16: =IF(OR(J16="",J16=0),"",I16&" -> "&$AK$2) -> #VALUE!
... A652: ='[1]2026 Orders'!A653 -> 0 | B652: ='[1]2026 Orders'!B653 -> 0 | C652: ='[1]2026 Orders'!C653 -> 0 | D652: ='[1]2026 Orders'!D653 -> 0 | E652: {=IF(C652=0,"", HYPERLINK( "#'2026 Orders'!C"& MATCH(1, ('2026 Orders'!C:C=C652)* ('2026 Orders'!G:G=G652)* ('2026 Orders'!N:N=N652), 0), "Open "&C652 ))} | F652: ='[1]2026 Orders'!F653 -> 0 | G652: ='[1]2026 Orders'!G653 -> 0 | H652: {=IFERROR(_xlfn.TEXTJOIN("-",,INDEX(_xlfn.TEXTSPLIT(TableTake[[#This Row],[SKU]],"-"),{1,2})),"")} | I652: =IFERROR(_xlfn.TEXTAFTER(TableTake[[#This Row],[SKU]],"-",-1),"") | J652: ='[1]2026 Orders'!H653 -> 0 | K652: ='[1]2026 Orders'!I653 -> 0 | L652: ='[1]2026 Orders'!J653 -> 0 | N652: ='[1]2026 Orders'!L653 -> 0 | O652: ='[1]2026 Orders'!M653 -> 0 | P652: ='[1]2026 Orders'!N653 -> 0 | Q652: ='[1]2026 Orders'!O653 -> 0 | R652: ='[1]2026 Orders'!P653 -> 0 | S652: ='[1]2026 Orders'!Q653 -> 0 | T652: ='[1]2026 Orders'!R653 -> 0 | U652: ='[1]2026 Orders'!S653 -> 0 | ... Z652: ='[1]2026 Orders'!X653 -> 0 | AC652: =IF(OR(B652="",B652=0),"",J652&"/"&$AJ$2) | AD652: =IF(OR(J652="",J652=0),"",I652&" -> "&$AK$2)

Sheet Allocation Dashboard (Give)
B1: Giving Opportunities | AG1: Product to Give | AK1: {=_xlfn.TEXTJOIN("-",,INDEX(_xlfn.TEXTSPLIT(AH2,"-"),{1,2}))} -> #VALUE!
A2: Date of Order | B2: Customer | C2: Order # | D2: Sales Personal Notes | E2: Order Details | F2: Notes: Include all notes week by week | G2: SKU | H2: Product | I2: Label | J2: QTY on Order | K2: Labels/IFC- Version/batch | L2: QTY Commited | M2: Column4 | N2: Status | O2: Notes | P2: IFC | Q2: UPC Code | R2: QTY on Order2 | S2: Item PO | T2: EST Manufacture Completion | U2: Notes: | V2: Lot Number | W2: Notes: Include all notes week by week3 | X2: Order ETA ** only for products in rework** | Y2: Date Completed D/W Sent | Z2: Status4 | AA2: Column2 | AB2: Column1 | AC2: QTY Fuffilled? | AD2: Peeling? | AE2: Column3 | AG2: SKU: | AI2: QTY: | AK2: =_xlfn.TEXTAFTER(AH2,"-", -1) -> #VALUE!
A3: ='[1]2026 Orders'!A4 -> 45726 | B3: ='[1]2026 Orders'!B4 -> China | C3: ='[1]2026 Orders'!C4 -> A4458 | D3: ='[1]2026 Orders'!D4 -> 0 | E3: {=IF(C3=0,"", HYPERLINK( "#'2026 Orders'!C"& MATCH(1, ('2026 Orders'!C:C=C3)* ('2026 Orders'!G:G=G3)* ('2026 Orders'!N:N=N3), 0), "Open "&C3 ))} -> Open A4458 | F3: ='[1]2026 Orders'!F4 -> 0 | G3: ='[1]2026 Orders'!G4 -> SELENIU-60-FD | H3: {=IFERROR(_xlfn.TEXTJOIN("-",,INDEX(_xlfn.TEXTSPLIT(TableGive[[#This Row],[SKU]],"-"),{1,2})),"")} -> SELENIU-60 | I3: =IFERROR(_xlfn.TEXTAFTER(TableGive[[#This Row],[SKU]],"-",-1),"") -> FD | J3: ='[1]2026 Orders'!H4 -> 200 | K3: ='[1]2026 Orders'!I4 -> F63-25.1 | L3: ='[1]2026 Orders'!J4 -> 0 | N3: ='[1]2026 Orders'!L4 -> D/W Sent | O3: ='[1]2026 Orders'!M4 -> 12/15 D/W Sent | P3: ='[1]2026 Orders'!N4 -> NA | Q3: ='[1]2026 Orders'!O4 -> 604776735762 | R3: ='[1]2026 Orders'!P4 -> 3000 | S3: ='[1]2026 Orders'!Q4 -> 4833 | T3: ='[1]2026 Orders'!R4 -> complete | U3: ='[1]2026 Orders'!S4 -> 0 | ... Z3: ='[1]2026 Orders'!X4 -> Approved 01/16/26 | AC3: =IF(OR(B3="",B3=0),"",$AJ$2&"/"&J3) -> /200 | AD3: =IF(OR(J3="",J3=0),"",$AK$2&" -> "&I3) -> #VALUE!
A4: ='[1]2026 Orders'!A5 -> 0 | B4: ='[1]2026 Orders'!B5 -> 0 | C4: ='[1]2026 Orders'!C5 -> 0 | D4: ='[1]2026 Orders'!D5 -> 0 | E4: {=IF(C4=0,"", HYPERLINK( "#'2026 Orders'!C"& MATCH(1, ('2026 Orders'!C:C=C4)* ('2026 Orders'!G:G=G4)* ('2026 Orders'!N:N=N4), 0), "Open "&C4 ))} | F4: ='[1]2026 Orders'!F5 -> 0 | G4: ='[1]2026 Orders'!G5 -> 0 | H4: {=IFERROR(_xlfn.TEXTJOIN("-",,INDEX(_xlfn.TEXTSPLIT(TableGive[[#This Row],[SKU]],"-"),{1,2})),"")} | I4: =IFERROR(_xlfn.TEXTAFTER(TableGive[[#This Row],[SKU]],"-",-1),"") | J4: ='[1]2026 Orders'!H5 -> 0 | K4: ='[1]2026 Orders'!I5 -> 0 | L4: ='[1]2026 Orders'!J5 -> 0 | N4: ='[1]2026 Orders'!L5 -> 0 | O4: ='[1]2026 Orders'!M5 -> 0 | P4: ='[1]2026 Orders'!N5 -> 0 | Q4: ='[1]2026 Orders'!O5 -> 0 | R4: ='[1]2026 Orders'!P5 -> 0 | S4: ='[1]2026 Orders'!Q5 -> 0 | T4: ='[1]2026 Orders'!R5 -> 0 | U4: ='[1]2026 Orders'!S5 -> 0 | ... Z4: ='[1]2026 Orders'!X5 -> 0 | AC4: =IF(OR(B4="",B4=0),"",$AJ$2&"/"&J4) | AD4: =IF(OR(J4="",J4=0),"",$AK$2&" -> "&I4)
A5: ='[1]2026 Orders'!A6 -> 45443 | B5: ='[1]2026 Orders'!B6 -> China | C5: ='[1]2026 Orders'!C6 -> A4425 | D5: ='[1]2026 Orders'!D6 -> 0 | E5: {=IF(C5=0,"", HYPERLINK( "#'2026 Orders'!C"& MATCH(1, ('2026 Orders'!C:C=C5)* ('2026 Orders'!G:G=G5)* ('2026 Orders'!N:N=N5), 0), "Open "&C5 ))} -> Open A4425 | F5: ='[1]2026 Orders'!F6 -> 0 | G5: ='[1]2026 Orders'!G6 -> VIACAL-60-FD | H5: {=IFERROR(_xlfn.TEXTJOIN("-",,INDEX(_xlfn.TEXTSPLIT(TableGive[[#This Row],[SKU]],"-"),{1,2})),"")} -> VIACAL-60 | I5: =IFERROR(_xlfn.TEXTAFTER(TableGive[[#This Row],[SKU]],"-",-1),"") -> FD | J5: ='[1]2026 Orders'!H6 -> 200 | K5: ='[1]2026 Orders'!I6 -> F66-22.1 | L5: ='[1]2026 Orders'!J6 -> 200 | N5: ='[1]2026 Orders'!L6 -> D/W Sent | O5: ='[1]2026 Orders'!M6 -> 01/13 D/W Sent | P5: ='[1]2026 Orders'!N6 -> NA | Q5: ='[1]2026 Orders'!O6 -> 609788968160 | R5: ='[1]2026 Orders'!P6 -> 2000 | S5: ='[1]2026 Orders'!Q6 -> 4661 | T5: ='[1]2026 Orders'!R6 -> complete | U5: ='[1]2026 Orders'!S6 -> 0 | ... Z5: ='[1]2026 Orders'!X6 -> Approved | AC5: =IF(OR(B5="",B5=0),"",$AJ$2&"/"&J5) -> /200 | AD5: =IF(OR(J5="",J5=0),"",$AK$2&" -> "&I5) -> #VALUE!
A6: ='[1]2026 Orders'!A7 -> 0 | B6: ='[1]2026 Orders'!B7 -> 0 | C6: ='[1]2026 Orders'!C7 -> 0 | D6: ='[1]2026 Orders'!D7 -> 0 | E6: {=IF(C6=0,"", HYPERLINK( "#'2026 Orders'!C"& MATCH(1, ('2026 Orders'!C:C=C6)* ('2026 Orders'!G:G=G6)* ('2026 Orders'!N:N=N6), 0), "Open "&C6 ))} | F6: ='[1]2026 Orders'!F7 -> 0 | G6: ='[1]2026 Orders'!G7 -> 0 | H6: {=IFERROR(_xlfn.TEXTJOIN("-",,INDEX(_xlfn.TEXTSPLIT(TableGive[[#This Row],[SKU]],"-"),{1,2})),"")} | I6: =IFERROR(_xlfn.TEXTAFTER(TableGive[[#This Row],[SKU]],"-",-1),"") | J6: ='[1]2026 Orders'!H7 -> 0 | K6: ='[1]2026 Orders'!I7 -> 0 | L6: ='[1]2026 Orders'!J7 -> 0 | N6: ='[1]2026 Orders'!L7 -> 0 | O6: ='[1]2026 Orders'!M7 -> 0 | P6: ='[1]2026 Orders'!N7 -> 0 | Q6: ='[1]2026 Orders'!O7 -> 0 | R6: ='[1]2026 Orders'!P7 -> 0 | S6: ='[1]2026 Orders'!Q7 -> 0 | T6: ='[1]2026 Orders'!R7 -> 0 | U6: ='[1]2026 Orders'!S7 -> 0 | ... Z6: ='[1]2026 Orders'!X7 -> 0 | AC6: =IF(OR(B6="",B6=0),"",$AJ$2&"/"&J6) | AD6: =IF(OR(J6="",J6=0),"",$AK$2&" -> "&I6)
A7: ='[1]2026 Orders'!A8 -> 45589 | B7: ='[1]2026 Orders'!B8 -> UAE | C7: ='[1]2026 Orders'!C8 -> A4624 | D7: ='[1]2026 Orders'!D8 -> Under going registration in UAE 5/13/2026: UAE unable to take, exploring if other clients can take product. | E7: {=IF(C7=0,"", HYPERLINK( "#'2026 Orders'!C"& MATCH(1, ('2026 Orders'!C:C=C7)* ('2026 Orders'!G:G=G7)* ('2026 Orders'!N:N=N7), 0), "Open "&C7 ))} -> #N/A | F7: ='[1]2026 Orders'!F8 -> 6/13/2025: products added from UAE A4393 9/5/2025: 96 packs allocated to Amazon 9/18/2025: Moved from A4445 | G7: ='[1]2026 Orders'!G8 -> NERUFLX-60-FD | H7: {=IFERROR(_xlfn.TEXTJOIN("-",,INDEX(_xlfn.TEXTSPLIT(TableGive[[#This Row],[SKU]],"-"),{1,2})),"")} -> NERUFLX-60 | I7: =IFERROR(_xlfn.TEXTAFTER(TableGive[[#This Row],[SKU]],"-",-1),"") -> FD | J7: ='[1]2026 Orders'!H8 -> 1054 | K7: ='[1]2026 Orders'!I8 -> F115-25.0 | L7: ='[1]2026 Orders'!J8 -> 1054 | N7: ='[1]2026 Orders'!L8 -> Sales Action Needed | O7: ='[1]2026 Orders'!M8 -> 01/20 D/W Sent | P7: ='[1]2026 Orders'!N8 -> Y | Q7: ='[1]2026 Orders'!O8 -> 810131193164 | R7: ='[1]2026 Orders'!P8 -> 2500 | S7: ='[1]2026 Orders'!Q8 -> 4524 | T7: ='[1]2026 Orders'!R8 -> complete | U7: ='[1]2026 Orders'!S8 -> 0 | ... Z7: ='[1]2026 Orders'!X8 -> HOLD | AC7: =IF(OR(B7="",B7=0),"",$AJ$2&"/"&J7) -> /1054 | AD7: =IF(OR(J7="",J7=0),"",$AK$2&" -> "&I7) -> #VALUE!
A8: ='[1]2026 Orders'!A9 -> 46058 | B8: ='[1]2026 Orders'!B9 -> 0 | C8: ='[1]2026 Orders'!C9 -> A4553 | D8: ='[1]2026 Orders'!D9 -> 5/13/2026: *DO NOT PREPARE ORDER FOR SHIPMENT YET: ADDITIONAL PRODUCTS TO BE ADDED* | E8: {=IF(C8=0,"", HYPERLINK( "#'2026 Orders'!C"& MATCH(1, ('2026 Orders'!C:C=C8)* ('2026 Orders'!G:G=G8)* ('2026 Orders'!N:N=N8), 0), "Open "&C8 ))} -> #N/A | F8: ='[1]2026 Orders'!F9 -> 3/30/2026: Moved from UAE A4644 | G8: ='[1]2026 Orders'!G9 -> MFSPLS-120-RE | H8: {=IFERROR(_xlfn.TEXTJOIN("-",,INDEX(_xlfn.TEXTSPLIT(TableGive[[#This Row],[SKU]],"-"),{1,2})),"")} -> MFSPLS-120 | I8: =IFERROR(_xlfn.TEXTAFTER(TableGive[[#This Row],[SKU]],"-",-1),"") -> RE | J8: ='[1]2026 Orders'!H9 -> 1050 | K8: ='[1]2026 Orders'!I9 -> 0 | L8: ='[1]2026 Orders'!J9 -> 1050 | N8: ='[1]2026 Orders'!L9 -> Picked | O8: ='[1]2026 Orders'!M9 -> 0 | P8: ='[1]2026 Orders'!N9 -> NA | Q8: ='[1]2026 Orders'!O9 -> 609788968344 | R8: ='[1]2026 Orders'!P9 -> 7000 | S8: ='[1]2026 Orders'!Q9 -> 4935 | T8: ='[1]2026 Orders'!R9 -> complete | U8: ='[1]2026 Orders'!S9 -> 0 | ... Z8: ='[1]2026 Orders'!X9 -> 0 | AC8: =IF(OR(B8="",B8=0),"",$AJ$2&"/"&J8) | AD8: =IF(OR(J8="",J8=0),"",$AK$2&" -> "&I8) -> #VALUE!
A9: ='[1]2026 Orders'!A10 -> 45880 | B9: ='[1]2026 Orders'!B10 -> Kuwait | C9: ='[1]2026 Orders'!C10 -> A4562 | D9: ='[1]2026 Orders'!D10 -> 5/11/2026: Order on hold | E9: {=IF(C9=0,"", HYPERLINK( "#'2026 Orders'!C"& MATCH(1, ('2026 Orders'!C:C=C9)* ('2026 Orders'!G:G=G9)* ('2026 Orders'!N:N=N9), 0), "Open "&C9 ))} -> Open A4562 | F9: ='[1]2026 Orders'!F10 -> 11/3/2025: Waiting for registration 11/5/2025: Allocated 500 packs to UAE A4521 | G9: ='[1]2026 Orders'!G10 -> EYECAP-30-FD | H9: {=IFERROR(_xlfn.TEXTJOIN("-",,INDEX(_xlfn.TEXTSPLIT(TableGive[[#This Row],[SKU]],"-"),{1,2})),"")} -> EYECAP-30 | I9: =IFERROR(_xlfn.TEXTAFTER(TableGive[[#This Row],[SKU]],"-",-1),"") -> FD | J9: ='[1]2026 Orders'!H10 -> 500 | K9: ='[1]2026 Orders'!I10 -> F15-26.0 | L9: ='[1]2026 Orders'!J10 -> 0 | N9: ='[1]2026 Orders'!L10 -> ON HOLD | O9: ='[1]2026 Orders'!M10 -> 0 | P9: ='[1]2026 Orders'!N10 -> Y | Q9: ='[1]2026 Orders'!O10 -> 609788968443 | R9: ='[1]2026 Orders'!P10 -> 0 | S9: ='[1]2026 Orders'!Q10 -> 0 | T9: ='[1]2026 Orders'!R10 -> 0 | U9: ='[1]2026 Orders'!S10 -> MOQ 5000 | ... Z9: ='[1]2026 Orders'!X10 -> HOLD | AC9: =IF(OR(B9="",B9=0),"",$AJ$2&"/"&J9) -> /500 | AD9: =IF(OR(J9="",J9=0),"",$AK$2&" -> "&I9) -> #VALUE!
A10: ='[1]2026 Orders'!A11 -> 46141 | B10: ='[1]2026 Orders'!B11 -> UAE | C10: ='[1]2026 Orders'!C11 -> A4553 | D10: ='[1]2026 Orders'!D11 -> 0 | E10: {=IF(C10=0,"", HYPERLINK( "#'2026 Orders'!C"& MATCH(1, ('2026 Orders'!C:C=C10)* ('2026 Orders'!G:G=G10)* ('2026 Orders'!N:N=N10), 0), "Open "&C10 ))} -> #N/A | F10: ='[1]2026 Orders'!F11 -> 4/29/2026: Product added 5/4/2026: Qty changed 183 -> 182 | G10: ='[1]2026 Orders'!G11 -> POLYSIT-90-RE | H10: {=IFERROR(_xlfn.TEXTJOIN("-",,INDEX(_xlfn.TEXTSPLIT(TableGive[[#This Row],[SKU]],"-"),{1,2})),"")} -> POLYSIT-90 | I10: =IFERROR(_xlfn.TEXTAFTER(TableGive[[#This Row],[SKU]],"-",-1),"") -> RE | J10: ='[1]2026 Orders'!H11 -> 182 | K10: ='[1]2026 Orders'!I11 -> 0 | L10: ='[1]2026 Orders'!J11 -> 182 | N10: ='[1]2026 Orders'!L11 -> 0 | O10: ='[1]2026 Orders'!M11 -> 182 available Lot: 49311125 | P10: ='[1]2026 Orders'!N11 -> Y | Q10: ='[1]2026 Orders'!O11 -> 609788969006 | R10: ='[1]2026 Orders'!P11 -> 0 | S10: ='[1]2026 Orders'!Q11 -> 0 | T10: ='[1]2026 Orders'!R11 -> 0 | U10: ='[1]2026 Orders'!S11 -> 0 | ... Z10: ='[1]2026 Orders'!X11 -> 0 | AC10: =IF(OR(B10="",B10=0),"",$AJ$2&"/"&J10) -> /182 | AD10: =IF(OR(J10="",J10=0),"",$AK$2&" -> "&I10) -> #VALUE!
A11: ='[1]2026 Orders'!A12 -> 45890 | B11: ='[1]2026 Orders'!B12 -> Uganda | C11: ='[1]2026 Orders'!C12 -> A4522 | D11: ='[1]2026 Orders'!D12 -> 0 | E11: {=IF(C11=0,"", HYPERLINK( "#'2026 Orders'!C"& MATCH(1, ('2026 Orders'!C:C=C11)* ('2026 Orders'!G:G=G11)* ('2026 Orders'!N:N=N11), 0), "Open "&C11 ))} -> Open A4522 | F11: ='[1]2026 Orders'!F12 -> 0 | G11: ='[1]2026 Orders'!G12 -> SPERMCT-60-FD | H11: {=IFERROR(_xlfn.TEXTJOIN("-",,INDEX(_xlfn.TEXTSPLIT(TableGive[[#This Row],[SKU]],"-"),{1,2})),"")} -> SPERMCT-60 | I11: =IFERROR(_xlfn.TEXTAFTER(TableGive[[#This Row],[SKU]],"-",-1),"") -> FD | J11: ='[1]2026 Orders'!H12 -> 96 | K11: ='[1]2026 Orders'!I12 -> F64-25.0 | L11: ='[1]2026 Orders'!J12 -> 96 | N11: ='[1]2026 Orders'!L12 -> Picked | O11: ='[1]2026 Orders'!M12 -> 0 | P11: ='[1]2026 Orders'!N12 -> NA | Q11: ='[1]2026 Orders'!O12 -> 609788968405 | R11: ='[1]2026 Orders'!P12 -> 5500 | S11: ='[1]2026 Orders'!Q12 -> 4850 | T11: ='[1]2026 Orders'!R12 -> complete | U11: ='[1]2026 Orders'!S12 -> 0 | ... Z11: ='[1]2026 Orders'!X12 -> HOLD | AC11: =IF(OR(B11="",B11=0),"",$AJ$2&"/"&J11) -> /96 | AD11: =IF(OR(J11="",J11=0),"",$AK$2&" -> "&I11) -> #VALUE!
A12: ='[1]2026 Orders'!A13 -> 45890 | B12: ='[1]2026 Orders'!B13 -> Uganda | C12: ='[1]2026 Orders'!C13 -> A4522 | D12: ='[1]2026 Orders'!D13 -> 0 | E12: {=IF(C12=0,"", HYPERLINK( "#'2026 Orders'!C"& MATCH(1, ('2026 Orders'!C:C=C12)* ('2026 Orders'!G:G=G12)* ('2026 Orders'!N:N=N12), 0), "Open "&C12 ))} -> Open A4522 | F12: ='[1]2026 Orders'!F13 -> 5/12/2026: Allocating to Lebanon A4690. | G12: ='[1]2026 Orders'!G13 -> WFSPLS-180-FD | H12: {=IFERROR(_xlfn.TEXTJOIN("-",,INDEX(_xlfn.TEXTSPLIT(TableGive[[#This Row],[SKU]],"-"),{1,2})),"")} -> WFSPLS-180 | I12: =IFERROR(_xlfn.TEXTAFTER(TableGive[[#This Row],[SKU]],"-",-1),"") -> FD | J12: ='[1]2026 Orders'!H13 -> 120 | K12: ='[1]2026 Orders'!I13 -> F73-23.0 | L12: ='[1]2026 Orders'!J13 -> 120 | N12: ='[1]2026 Orders'!L13 -> PO Drafted | O12: ='[1]2026 Orders'!M13 -> 46012 | P12: ='[1]2026 Orders'!N13 -> NA | Q12: ='[1]2026 Orders'!O13 -> 609788968351 | R12: ='[1]2026 Orders'!P13 -> 5000 | S12: ='[1]2026 Orders'!Q13 -> 5043 | T12: ='[1]2026 Orders'!R13 -> TBD | U12: ='[1]2026 Orders'!S13 -> Pending approval to send to vendor | ... Z12: ='[1]2026 Orders'!X13 -> 0 | AC12: =IF(OR(B12="",B12=0),"",$AJ$2&"/"&J12) -> /120 | AD12: =IF(OR(J12="",J12=0),"",$AK$2&" -> "&I12) -> #VALUE!
A13: ='[1]2026 Orders'!A14 -> 45890 | B13: ='[1]2026 Orders'!B14 -> Uganda | C13: ='[1]2026 Orders'!C14 -> A4522 | D13: ='[1]2026 Orders'!D14 -> 0 | E13: {=IF(C13=0,"", HYPERLINK( "#'2026 Orders'!C"& MATCH(1, ('2026 Orders'!C:C=C13)* ('2026 Orders'!G:G=G13)* ('2026 Orders'!N:N=N13), 0), "Open "&C13 ))} -> Open A4522 | F13: ='[1]2026 Orders'!F14 -> 9/11/2025: product changed to RE 5/14/2026: Allocate to Cyprus A4675. | G13: ='[1]2026 Orders'!G14 -> FERTMX-90-RE | H13: {=IFERROR(_xlfn.TEXTJOIN("-",,INDEX(_xlfn.TEXTSPLIT(TableGive[[#This Row],[SKU]],"-"),{1,2})),"")} -> FERTMX-90 | I13: =IFERROR(_xlfn.TEXTAFTER(TableGive[[#This Row],[SKU]],"-",-1),"") -> RE | J13: ='[1]2026 Orders'!H14 -> 288 | K13: ='[1]2026 Orders'!I14 -> R16-22.0 | L13: ='[1]2026 Orders'!J14 -> 0 | N13: ='[1]2026 Orders'!L14 -> PO submitted | O13: ='[1]2026 Orders'!M14 -> 0 | P13: ='[1]2026 Orders'!N14 -> Y | Q13: ='[1]2026 Orders'!O14 -> 609788968726 | R13: ='[1]2026 Orders'!P14 -> 5000 | S13: ='[1]2026 Orders'!Q14 -> 5041 | T13: ='[1]2026 Orders'!R14 -> TBD | U13: ='[1]2026 Orders'!S14 -> Waiting for vendor confirmation. | ... Z13: ='[1]2026 Orders'!X14 -> 0 | AC13: =IF(OR(B13="",B13=0),"",$AJ$2&"/"&J13) -> /288 | AD13: =IF(OR(J13="",J13=0),"",$AK$2&" -> "&I13) -> #VALUE!
A14: ='[1]2026 Orders'!A15 -> 45890 | B14: ='[1]2026 Orders'!B15 -> Uganda | C14: ='[1]2026 Orders'!C15 -> A4522 | D14: ='[1]2026 Orders'!D15 -> 0 | E14: {=IF(C14=0,"", HYPERLINK( "#'2026 Orders'!C"& MATCH(1, ('2026 Orders'!C:C=C14)* ('2026 Orders'!G:G=G14)* ('2026 Orders'!N:N=N14), 0), "Open "&C14 ))} -> Open A4522 | F14: ='[1]2026 Orders'!F15 -> 0 | G14: ='[1]2026 Orders'!G15 -> PRECON-90-FD | H14: {=IFERROR(_xlfn.TEXTJOIN("-",,INDEX(_xlfn.TEXTSPLIT(TableGive[[#This Row],[SKU]],"-"),{1,2})),"")} -> PRECON-90 | I14: =IFERROR(_xlfn.TEXTAFTER(TableGive[[#This Row],[SKU]],"-",-1),"") -> FD | J14: ='[1]2026 Orders'!H15 -> 120 | K14: ='[1]2026 Orders'!I15 -> F54-23.0 | L14: ='[1]2026 Orders'!J15 -> 120 | N14: ='[1]2026 Orders'!L15 -> Picked | O14: ='[1]2026 Orders'!M15 -> 0 | P14: ='[1]2026 Orders'!N15 -> NA | Q14: ='[1]2026 Orders'!O15 -> 609788968368 | R14: ='[1]2026 Orders'!P15 -> 7500 | S14: ='[1]2026 Orders'!Q15 -> 4714 | T14: ='[1]2026 Orders'!R15 -> complete | U14: ='[1]2026 Orders'!S15 -> 0 | ... Z14: ='[1]2026 Orders'!X15 -> 0 | AC14: =IF(OR(B14="",B14=0),"",$AJ$2&"/"&J14) -> /120 | AD14: =IF(OR(J14="",J14=0),"",$AK$2&" -> "&I14) -> #VALUE!
... A652: ='[1]2026 Orders'!A653 -> 0 | B652: ='[1]2026 Orders'!B653 -> 0 | C652: ='[1]2026 Orders'!C653 -> 0 | D652: ='[1]2026 Orders'!D653 -> 0 | E652: {=IF(C652=0,"", HYPERLINK( "#'2026 Orders'!C"& MATCH(1, ('2026 Orders'!C:C=C652)* ('2026 Orders'!G:G=G652)* ('2026 Orders'!N:N=N652), 0), "Open "&C652 ))} | F652: ='[1]2026 Orders'!F653 -> 0 | G652: ='[1]2026 Orders'!G653 -> 0 | H652: {=IFERROR(_xlfn.TEXTJOIN("-",,INDEX(_xlfn.TEXTSPLIT(TableGive[[#This Row],[SKU]],"-"),{1,2})),"")} | I652: =IFERROR(_xlfn.TEXTAFTER(TableGive[[#This Row],[SKU]],"-",-1),"") | J652: ='[1]2026 Orders'!H653 -> 0 | K652: ='[1]2026 Orders'!I653 -> 0 | L652: ='[1]2026 Orders'!J653 -> 0 | N652: ='[1]2026 Orders'!L653 -> 0 | O652: ='[1]2026 Orders'!M653 -> 0 | P652: ='[1]2026 Orders'!N653 -> 0 | Q652: ='[1]2026 Orders'!O653 -> 0 | R652: ='[1]2026 Orders'!P653 -> 0 | S652: ='[1]2026 Orders'!Q653 -> 0 | T652: ='[1]2026 Orders'!R653 -> 0 | U652: ='[1]2026 Orders'!S653 -> 0 | ... Z652: ='[1]2026 Orders'!X653 -> 0 | AC652: =IF(OR(B652="",B652=0),"",$AJ$2&"/"&J652) | AD652: =IF(OR(J652="",J652=0),"",$AK$2&" -> "&I652)

Sheet 2026 Orders
B1: Customer | C1: Order # | D1: Sales Personal Notes | E1: Order Notes | F1: Notes: Include all notes week by week | G1: SKU | H1: Product | I1: Label | J1: QTY on Order | K1: Labels/IFC- Version/batch | L1: QTY Commited | M1: QTY Needed | N1: Status | Q1: ANALYSIS DIRECTIONS: 1. Click any cell related to desired product 2. Click the button of desired analysis
B2: China | C2: A4458 | D2: 0 | E2: 5/20/2025: Back order created for China A4412 11/3/2025: PediaFl removed 1/14/2025 Documents & D/Ws Sent | F2: 0 | G2: SELENIU-60-FD | H2: SELENIU-60 | I2: FD | J2: 200 | K2: F63-25.1 | L2: 0 | M2: 200 | N2: D/W Sent
B3: 0 | C3: 0 | D3: 0 | E3: 0 | F3: 0 | G3: 0 | J3: 0 | K3: 0 | L3: 0 | M3: 0 | N3: 0
B4: China | C4: A4425 | D4: 0 | E4: 07/29/2024: Back order for China A4259 3/20/2025: Back order from A4281 8/22/2025: Docs & D/Ws Sent 11/7/2025: Pedia Products removed 12/12/2025: prosta moved to A4607 1/13/2025: Updated Documents and D/Ws Sent | F4: 0 | G4: VIACAL-60-FD | H4: VIACAL-60 | I4: FD | J4: 200 | K4: F66-22.1 | L4: 200 | M4: 0 | N4: D/W Sent
B5: 0 | C5: 0 | D5: 0 | E5: 0 | F5: 0 | G5: 0 | J5: 0 | K5: 0 | L5: 0 | M5: 0 | N5: 0
B6: UAE | C6: A4624 | D6: Under going registration in UAE 5/13/2026: UAE unable to take, exploring if other clients can take product. | E6: Split from UAE A4553 because product is undergoing registration | F6: 6/13/2025: products added from UAE A4393 9/5/2025: 96 packs allocated to Amazon 9/18/2025: Moved from A4445 | G6: NERUFLX-60-FD | H6: NERUFLX-60 | I6: FD | J6: 1054 | K6: F115-25.0 | L6: 1054 | M6: 0 | N6: D/W Sent
B7: 0 | C7: 0 | D7: 0 | E7: 0 | F7: 0 | G7: 0 | J7: 0 | K7: 0 | L7: 0 | M7: 0 | N7: 0
B8: Kuwait | C8: A4562 | D8: 5/11/2026: Order on hold | E8: 11/3/2025: 2025 Back Order for Kuwait A4505 **MUST BE GREEN CAPSULE** | F8: 11/3/2025: Waiting for registration 11/5/2025: Allocated 500 packs to UAE A4521 | G8: EYECAP-30-FD | H8: EYECAP-30 | I8: FD | J8: 500 | K8: F15-26.0 | L8: 0 | M8: 500 | N8: ON HOLD
B9: 0 | C9: 0 | D9: 0 | E9: 0 | F9: 0 | G9: 0 | J9: 0 | K9: 0 | L9: 0 | M9: 0 | N9: 0
B10: Uganda | C10: A4522 | D10: 0 | E10: 9/10/2025- Split from A4507 10/30/2025: Documents Sent 11/3/2025: Estimate W/Ds Sent 12/12/2025 Documents sent 12/21/2025 Final D/Ws Sent **UPDATED DOCS NEEDED** | F10: 0 | G10: SPERMCT-60-FD | H10: SPERMCT-60 | I10: FD | J10: 96 | K10: F64-25.0 | L10: 96 | M10: 0 | N10: Picked
B11: Uganda | C11: A4522 | D11: 0 | E11: 0 | F11: 5/12/2026: Allocating to Lebanon A4690. | G11: WFSPLS-180-FD | H11: WFSPLS-180 | I11: FD | J11: 120 | K11: F73-23.0 | L11: 120 | M11: 0 | N11: PO Drafted
B12: Uganda | C12: A4522 | D12: 0 | E12: 0 | F12: 9/11/2025: product changed to RE 5/14/2026: Allocate to Cyprus A4675. | G12: FERTMX-90-RE | H12: FERTMX-90 | I12: RE | J12: 288 | K12: R16-22.0 | L12: 0 | M12: 288 | N12: PO submitted
B13: Uganda | C13: A4522 | D13: 0 | E13: 0 | F13: 0 | G13: PRECON-90-FD | H13: PRECON-90 | I13: FD | J13: 120 | K13: F54-23.0 | L13: 120 | M13: 0 | N13: Picked
B14: Uganda | C14: A4522 | D14: 0 | E14: 0 | F14: 0 | G14: QWELL4-30-SG-FD | H14: QWELL4-30 | I14: FD | J14: 96 | K14: F58-25.3 | L14: 96 | M14: 0 | N14: Picked
B15: Uganda | C15: A4522 | D15: 0 | E15: 0 | F15: 0 | G15: PROSTA-90-FD | H15: PROSTA-90 | I15: FD | J15: 24 | K15: F56-23.0 | L15: 24 | M15: 0 | N15: Picked
B16: Uganda | C16: A4522 | D16: 0 | E16: 0 | F16: 12/4/2025: Moved From UgandaA4534 4/9/2026: 192 packs of Ovamax allocated to Bahrain A4685 | G16: OVAMAX-120-FD | H16: OVAMAX-120 | I16: FD | J16: 192 | K16: F41-25.0 | L16: 0 | M16: 192 | N16: In Production
B17: Uganda | C17: A4522 | D17: 0 | E17: 0 | F17: 0 | G17: WFSPLS-180-FD | H17: WFSPLS-180 | I17: FD | J17: 48 | K17: F73-23.0 | L17: 0 | M17: 48 | N17: Picked
B18: Uganda | C18: A4522 | D18: 0 | E18: 0 | F18: 0 | G18: FERTMX-90-RE | H18: FERTMX-90 | I18: RE | J18: 40 | K18: R16-22.0 | L18: 40 | M18: 0 | N18: Picked
B19: Uganda | C19: A4522 | D19: 0 | E19: 0 | F19: 4/2/2026: FERTMX-90-RE 200 packs allocated to Doreen A4678 | G19: FERTMX-90-RE | H19: FERTMX-90 | I19: RE | J19: 200 | K19: R16-22.0 | L19: 0 | M19: 200 | N19: PO submitted
B20: Uganda | C20: A4522 | D20: 2/11/2026: Updated IFC to Y after IFC scrub. | E20: 0 | F20: 0 | G20: PENAMAX-60-GE-FD | H20: PENAMAX-60 | I20: FD | J20: 96 | K20: F88-25.1 | L20: 96 | M20: 0 | N20: Picked
B21: Uganda | C21: A4522 | D21: 0 | E21: 0 | F21: 03/10/26 Product allocated to Somalia A4655 | G21: DHEA50-60-FD | H21: DHEA50-60 | I21: FD | J21: 72 | K21: F13-25.2 | L21: 0 | M21: 72 | N21: In Production
B22: Uganda | C22: A4522 | D22: 0 | E22: 0 | F22: 12/4/2025: Moved From UgandaA4534 | G22: QWELL4-30-SG-FD | H22: QWELL4-30 | I22: FD | J22: 48 | K22: F58-25.3 | L22: 48 | M22: 0 | N22: Picked
B23: Uganda | C23: A4522 | D23: 0 | E23: 0 | F23: 0 | G23: PRECON-180-FD | H23: PRECON-180 | I23: FD | J23: 50 | K23: F55-22.2 | L23: 0 | M23: 50 | N23: In Production
B24: 0 | C24: 0 | D24: 0 | E24: 0 | F24: 0 | G24: 0 | J24: 0 | K24: 0 | L24: 0 | M24: 0 | N24: 0
B25: Morocco | C25: A4518 | D25: Awaiting customer update | E25: Sample Order: Use plain white labels with only the product name and batch number 9/8/2025: Documents Sent 9/29/2025: Docs & D/Ws Sent 10/17/2025: NMNH Added | F25: 0 | G25: MOTILMX-60-FD | H25: MOTILMX-60 | I25: FD | J25: 1 | K25: F31-23.0 | L25: 1 | M25: 0 | N25: D/W Sent
B26: Morocco | C26: A4518 | D26: 0 | E26: 0 | F26: 0 | G26: MFSPLS-60-FD | H26: MFSPLS-60 | I26: FD | J26: 1 | K26: F29-25.0 | L26: 1 | M26: 0 | N26: D/W Sent
B27: Morocco | C27: A4518 | D27: 0 | E27: 0 | F27: 0 | G27: MFSPLS-120-FD | H27: MFSPLS-120 | I27: FD | J27: 1 | K27: F30-25.1 | L27: 1 | M27: 0 | N27: D/W Sent
B28: Morocco | C28: A4518 | D28: 0 | E28: 0 | F28: 0 | G28: POLYSIT-90-FD | H28: POLYSIT-90 | I28: FD | J28: 1 | K28: F53-14.0 | L28: 1 | M28: 0 | N28: D/W Sent
B29: Morocco | C29: A4518 | D29: 0 | E29: 0 | F29: 0 | G29: PENAMAX-60-GE-FD | H29: PENAMAX-60 | I29: FD | J29: 1 | K29: F88-25.1 | L29: 1 | M29: 0 | N29: D/W Sent
B30: Morocco | C30: A4518 | D30: 0 | E30: 0 | F30: 0 | G30: FERTMX-90-RE | H30: FERTMX-90 | I30: RE | J30: 1 | K30: R16-22.0 | L30: 1 | M30: 0 | N30: D/W Sent
B31: Morocco | C31: A4518 | D31: 0 | E31: 0 | F31: 0 | G31: OVAMAX-120-FD | H31: OVAMAX-120 | I31: FD | J31: 1 | K31: F41-25.0 | L31: 1 | M31: 0 | N31: D/W Sent
B32: Morocco | C32: A4518 | D32: 0 | E32: 0 | F32: 10/17/2025: Added to order | G32: NMNH-60-FD | H32: NMNH-60 | I32: FD | J32: 3 | K32: F114-25.0 | L32: 3 | M32: 0 | N32: D/W Sent
B33: 0 | C33: 0 | D33: 0 | E33: 0 | F33: 0 | G33: 0 | J33: 0 | K33: 0 | L33: 0 | M33: 0 | N33: 0
B34: China | C34: A4637 | D34: 0 | E34: 1/27/2025: split order from China A4520 due to registration issues 2/2/2026: Documents and D/Ws sent | F34: 9/29/2025: Sku updated | G34: OVAMAXPLUS-120-CS-CN | H34: OVAMAXPLUS-120 | I34: CN | J34: 1100 | K34: CN41-25.0 | L34: 1100 | M34: 0 | N34: D/W Sent
B35: 0 | C35: 0 | D35: 0 | E35: 0 | F35: 0 | G35: 0 | J35: 0 | K35: 0 | L35: 0 | M35: 0 | N35: 0
B36: Jordan | C36: A4646 | D36: 6/1/2026: Products arriving to AMS warehouse on 6/4/2026. | E36: Jordan Sample Count Order (5-day Supply) 3/11/2026: Documents sent 5/5/2026: D/W sent | F36: 0 | G36: FIBRO-10-CS-JO | H36: FIBRO-10 | I36: JO | J36: 420 | K36: JO130-25.0 | L36: 0 | M36: 420 | N36: Available
B37: Jordan | C37: A4646 | D37: 0 | E37: 0 | F37: 0 | G37: WFSPLS-30-CS-JO | H37: WFSPLS-30 | I37: JO | J37: 345 | K37: JO132-25.1 | L37: 0 | M37: 345 | N37: Available
B38: Jordan | C38: A4646 | D38: 0 | E38: 0 | F38: 0 | G38: OVAMAX-20-CS-JO | H38: OVAMAX-20 | I38: JO | J38: 300 | K38: JO131-25.0 | L38: 0 | M38: 300 | N38: Available
B39: Jordan | C39: A4646 | D39: 0 | E39: 0 | F39: 0 | G39: DHEA50-5-CS-JO | H39: DHEA50-5 | I39: JO | J39: 300 | K39: JO133-25.0 | L39: 0 | M39: 300 | N39: Available
B40: 0 | C40: 0 | D40: 0 | E40: 0 | F40: 0 | G40: 0 | J40: 0 | K40: 0 | L40: 0 | M40: 0 | N40: 0
...
